Workbook

Sheet Deal Overview and Outputs
A2: Deal Overview | B2: Values | D2: Base Case Returns | E2: Values
A3: Sponsor | B3: Appolo | D3: Equity Invested
A4: Target | B4: ADT | D4: Equity Proceeds | E4: 2650
A5: Type | B5: Public - Private LBO
A6: Year of Acquiring | B6: Feb, 2016 | D6: Gross IRR | E6: 0.12
A7: Hold Period | B7: 5 Years | D7: MOIC | E7: 0.0175
A10: Key Transaction Metrics | B10: Values | D10: Key Assumptions | E10: Values
A11: Entry EBITDA | D11: Revenue CGAR
A12: Entry EBITDA Multiples | D12: Exit EBITDA Margin
A13: Enterprise Value | D13: Capex(% of Revenue)
A14: Debt at Entry | D14: Change in NWC (% of revneue)
A15: Equity Contribution | D15: Exit Multiples
A16: Debt %
A17: Equity Percentage

Sheet Sources and Uses
A1: Sponsor | B1: Appolo
A2: Target | B2: ADT
A3: Type | B3: Public - Private LBO
A4: Year of Acquiring | B4: Feb, 2016
A5: Hold Period | B5: 5 Years
A7: Sources | B7: Values | D7: Metrics | E7: Values
A8: Term laon B | B8: 3800 | D8: Equity Purchase Price | E8: 6900
A9: Optional Second Lien Notes | B9: 0 | D9: Refinance and Existing Debt | E9: 1200
A10: Sponsor Equity | B10: 4520 | D10: Transaction Fees | E10: 100
A11: Total Sources | B11: =B10+B8 -> 8320 | D11: Financing fees | E11: 120
D12: Total Uses | E12: =SUM(E8:E11) -> 8320

Sheet Trasaction & Operating Assump,
A2: Trasaction Assumptions | B2: Values
A3: Entry Year | B3: 2017 | D3: Operating Base | E3: Values
A4: Exit Year | B4: 2022 | D4: Revenue Growth | E4: 0.03
A5: Holding Period | B5: 5 Years | D5: EBITDA Margin | E5: 921
D6: EBITDA Margin | E6: =E5/'Trasaction & Operating Assump,'!E30*100% -> 0.25769446
A7: Metrics | B7: Values | D7: FCF | E7: 244
A8: Entry EV/ EBITDA
A9: Exit EV/ EBITDA | D9: Cash Flow Assumptions | E9: Values
D10: CAPEX ( % of Revenue) | E10: 103
A11: Trsaction Fees (% of EBITDA) | D11: D&A(% Of Revenue) | E11: 9095
A12: Financing Fees (% of EBITDA) | D12: Cash Tax Rate | E12: 0.25
D13: NWC(% of Revenue) | E13: 0.01
A14: Operating Assumptions | B14: Values
A15: Revenue Growth | B15: 0.03 | D15: Entry Valuation | E15: Values
A16: EBITDA Margin (Entry) | B16: 0.258 | D16: Entry EBITDA | E16: 921
A17: EBITDA Margin (Exit) | D17: Entry EV | E17: 3574
A18: Margin Expansion bps | D18: Entry Multiples | E18: =E17/E16 -> 3.8805646
A20: Cash Flow Assumptions | B20: Values | D20: Projections Assumptions | E20: Values
A21: Cash Tax Rate | B21: 0.25 | D21: Revenue Grwoth | E21: 0.03
A22: Capex (% of Revenue) | B22: 0.03 | D22: EBITDA Margin | E22: 0.258
A23: D&A( % of revenue) | B23: 0.035 | D23: Hold Period | E23: 5Years
A24: Change in NWC (% of Revenue) | B24: 0.01 | D24: Exit Multiples | E24: 7.5
A26: Financing Assumption | B26: Values | D26: Column1 | E26: Column2
A27: Interest Rate (%) | B27: 0.085 | D27: Purchase Price Per share | E27: 42
A28: Mandatory Assumptions (%) | B28: 0.01 | D28: Fully Diluted shares | E28: 164
A29: Cash Sweep (% or Toggle)
D30: Enterpeise Value | E30: 3574
D31: Transaction Fees( % of EV) | E31: 0.015
D32: Financing Fees( % of Debt) | E32: 0.02

Sheet Operating Model
A1: Sponsor | B1: Appolo
A2: Target | B2: ADT
A3: Type | B3: Public - Private LBO
A4: Year of Acquiring | B4: Feb, 2016
A5: Hold Period | B5: 5 Years
A7: Metrics | B7: Base Year 2016 | C7: Year 1 | D7: Year 2 | E7: Year 3 | F7: Year 4 | G7: Year 5
A8: Revenue | B8: 3574 | C8: =B9*B8+B8 -> 3681.22 | D8: =C9*C8+C8 -> 3791.6566 | E8: =D9*D8+D8 -> 3905.4063 | F8: =E9*E8+E8 -> 4022.5685 | G8: =F9*F8+F8 -> 4143.2455
A9: % Growth | B9: 0.03 | C9: 0.03 | D9: 0.03 | E9: 0.03 | F9: 0.03 | G9: 0.03
A10: EBITDA | B10: 921 | C10: =C11*C8 -> 948.63 | D10: =D11*D8 -> 977.0889 | E10: =E11*E8 -> 1015.4056 | F10: =F11*F8 -> 1053.9129 | G10: =G11*G8 -> 1093.8168
A11: EBITDA Margin | B11: =B10/B8 -> 0.25769446 | C11: 0.25769446 | D11: 0.25769446 | E11: 0.26 | F11: 0.262 | G11: 0.264
A12: D&A | B12: =0.035*B8 -> 125.09 | C12: =0.035*C8 -> 128.8427 | D12: =0.035*D8 -> 132.70798 | E12: =0.035*E8 -> 136.68922 | F12: =0.035*F8 -> 140.7899 | G12: =0.035*G8 -> 145.01359
A13: D&A % of Revenue | B13: 0.035 | C13: 0.035 | D13: 0.035 | E13: 0.035 | F13: 0.035 | G13: 0.035
A14: EBIT | B14: =B10-B12 -> 795.91 | C14: =C10-C12 -> 819.7873 | D14: =D10-D12 -> 844.38092 | E14: =E10-E12 -> 878.71642 | F14: =F10-F12 -> 913.12305 | G14: =G10-G12 -> 948.80323
A15: Cash Tax (% ) | B15: 0.25 | C15: 0.25 | D15: 0.25 | E15: 0.25 | F15: 0.25 | G15: 0.25
A16: Cash Taxes | B16: =0.25*B14 -> 198.9775 | C16: =0.25*C14 -> 204.94682 | D16: =0.25*D14 -> 211.09523 | E16: =0.25*E14 -> 219.6791 | F16: =0.25*F14 -> 228.28076 | G16: =0.25*G14 -> 237.20081
A17: NOPAT | B17: =B14-B16 -> 596.9325 | C17: =C14-C16 -> 614.84047 | D17: =D14-D16 -> 633.28569 | E17: =E14-E16 -> 659.03731 | F17: =F14-F16 -> 684.84228 | G17: =G14-G16 -> 711.60242
A18: CapEx % | B18: 0.03 | C18: 0.03 | D18: 0.03 | E18: 0.03 | F18: 0.03 | G18: 0.03
A19: CapEX | B19: =B18*B8 -> 107.22 | C19: =C18*C8 -> 110.4366 | D19: =D18*D8 -> 113.7497 | E19: =E18*E8 -> 117.16219 | F19: =F18*F8 -> 120.67705 | G19: =G18*G8 -> 124.29737
A20: Change in NWC 1% of Change in Revenue | C20: 0.01 | D20: 0.01 | E20: 0.01 | F20: 0.01 | G20: 0.01
A21: Change in NWC | C21: 1.07 | D21: 1.1 | E21: 1.14 | F21: 1.17 | G21: 1.21
A22: UFCF | C22: =C17+C12-C19-C21 -> 632.17657 | D22: =D17+D12-D19-D21 -> 651.14397 | E22: =E17+E12-E19-E21 -> 677.42434 | F22: =F17+F12-F19-F21 -> 703.78513 | G22: =G17+G12-G19-G21 -> 731.10865
C48: Capital Structure Disciplined Assumptions | D48: Values
C49: Sponsor Equity | D49: 0.45
C50: Sponsor Debt | D50: 0.55

Sheet Cash Flows and Cash Sweep
A2: Sponsor | B2: Appolo
A3: Target | B3: ADT
A4: Type | B4: Public - Private LBO
A5: Year of Acquiring | B5: Feb, 2016
A6: Hold Period | B6: 5 Years
A14: Metrics | B14: Year 1 | C14: Year 2 | D14: Year 3 | E14: Year 4 | F14: Year 5
A15: Unlevered Free Cash Flow | B15: ='Operating Model'!C22 -> 632.17657 | C15: ='Operating Model'!D22 -> 651.14397 | D15: ='Operating Model'!E22 -> 677.42434 | E15: ='Operating Model'!F22 -> 703.78513 | F15: ='Operating Model'!G22 -> 731.10865
A16: Begining Cash Balance | B16: 0 | C16: 0 | D16: 0 | E16: 0 | F16: 0
A17: cash Aviablable for Debt Payments | B17: =B15 -> 632.17657 | C17: =C15 -> 651.14397 | D17: =D15 -> 677.42434 | E17: =E15 -> 703.78513 | F17: =F15 -> 731.10865
A18: Mandatory Ammortization % | B18: 0.01 | C18: 0.01 | D18: 0.01 | E18: 0.01 | F18: 0.01
A19: Mandatory Ammortization | B19: =B18*'Operating Model'!C8 -> 36.8122 | C19: =C18*'Operating Model'!D8 -> 37.916566 | D19: =D18*'Operating Model'!E8 -> 39.054063 | E19: =E18*'Operating Model'!F8 -> 40.225685 | F19: =F18*'Operating Model'!G8 -> 41.432455
A20: Cash Sweep | B20: ='Debt Schedule'!C24 -> 633.24657 | C20: ='Debt Schedule'!D24 -> 652.23397 | D20: ='Debt Schedule'!E24 -> 678.55434 | E20: ='Debt Schedule'!F24 -> 704.94513 | F20: ='Debt Schedule'!G24 -> 732.30865
A21: Ending Cash Balance | B21: 0 | C21: 0 | D21: 0 | E21: 0 | F21: 0

Sheet Debt Schedule
A1: Sponsor | B1: Appolo
A2: Target | B2: ADT
A3: Type | B3: Public - Private LBO
A4: Year of Acquiring | B4: Feb, 2016
A5: Hold Period | B5: 5 Years
A7: Metrics | B7: Base Year | C7: Year 1 | D7: Year 2 | E7: Year 3 | F7: Year 4 | G7: Year 5
A8: Beginning Balance | B8: 3800 | C8: =B12 -> 3800 | D8: =C12 -> 3128.7534 | E8: =D12 -> 2445.2319 | F8: =E12 -> 1742.2253 | G8: =F12 -> 1019.8579
A9: Mandatory Ammortizatiion % | B9: 0.01 | C9: 0.01 | D9: 0.01 | E9: 0.01 | F9: 0.01 | G9: 0.01
A10: Mandatory Ammortizatiion % | C10: =C9*C8 -> 38 | D10: =D9*D8 -> 31.287534 | E10: =E9*E8 -> 24.452319 | F10: =F9*F8 -> 17.422253 | G10: =G9*G8 -> 10.198579
A11: Cash Sweep | C11: =C23 -> 633.24657 | D11: =D23 -> 652.23397 | E11: =E23 -> 678.55434 | F11: =F23 -> 704.94513 | G11: =G23 -> 732.30865
A12: Ending Balance | B12: =B8-B10-B11 -> 3800 | C12: =C8-C10-C11 -> 3128.7534 | D12: =D8-D10-D11 -> 2445.2319 | E12: =E8-E10-E11 -> 1742.2253 | F12: =F8-F10-F11 -> 1019.8579 | G12: =G8-G10-G11 -> 277.35065
A13: Average Balance | C13: =AVERAGE(C8,C12) -> 3464.3767 | D13: =AVERAGE(D8,D12) -> 2786.9927 | E13: =AVERAGE(E8,E12) -> 2093.7286 | F13: =AVERAGE(F8,F12) -> 1381.0416 | G13: =AVERAGE(G8,G12) -> 648.60426
A14: Interest Rate | C14: 0.085 | D14: 0.085 | E14: 0.085 | F14: 0.085 | G14: 0.085
A15: Interest Expenses | C15: =C14*C13 -> 294.47202 | D15: =D14*D13 -> 236.89438 | E15: =E14*E13 -> 177.96693 | F15: =F14*F13 -> 117.38853 | G15: =G14*G13 -> 55.131362
A18: Cash Flow | B18: Base Year | C18: Year 1 | D18: Year 2 | E18: Year 3 | F18: Year 4 | G18: Year 5
A19: EBITDA | C19: ='Operating Model'!C10 -> 948.63 | D19: ='Operating Model'!D10 -> 977.0889 | E19: ='Operating Model'!E10 -> 1015.4056 | F19: ='Operating Model'!F10 -> 1053.9129 | G19: ='Operating Model'!G10 -> 1093.8168
A20: Less : Cash Taxes | C20: ='Operating Model'!C16 -> 204.94682 | D20: ='Operating Model'!D16 -> 211.09523 | E20: ='Operating Model'!E16 -> 219.6791 | F20: ='Operating Model'!F16 -> 228.28076 | G20: ='Operating Model'!G16 -> 237.20081
A21: Less Capex | C21: ='Operating Model'!C19 -> 110.4366 | D21: ='Operating Model'!D19 -> 113.7497 | E21: ='Operating Model'!E19 -> 117.16219 | F21: ='Operating Model'!F19 -> 120.67705 | G21: ='Operating Model'!G19 -> 124.29737
A22: Less Change in NWC | C22: 0 | D22: ='Operating Model'!D20 -> 0.01 | E22: ='Operating Model'!E20 -> 0.01 | F22: ='Operating Model'!F20 -> 0.01 | G22: ='Operating Model'!G20 -> 0.01
A23: Cash Available for Debt repayment | C23: =C19-C20-C21-C22 -> 633.24657 | D23: =D19-D20-D21-D22 -> 652.23397 | E23: =E19-E20-E21-E22 -> 678.55434 | F23: =F19-F20-F21-F22 -> 704.94513 | G23: =G19-G20-G21-G22 -> 732.30865
A24: Cash Sweep | C24: =MIN(C23,C8-C10) -> 633.24657 | D24: =MIN(D23,D8-D10) -> 652.23397 | E24: =MIN(E23,E8-E10) -> 678.55434 | F24: =MIN(F23,F8-F10) -> 704.94513 | G24: =MIN(G23,G8-G10) -> 732.30865

Sheet Returns and Senstivities
A1: Entry Exit Cash Flow Bridge | B1: Values
A2: Holding Period | B2: 5
A4: Entry Enterprise Value | B4: 4520
A5: Net Debt | B5: 2712
A6: Equity Invested | B6: =B4-B5 -> 1808
A8: Exit EBITDA | B8: 1093.8
A9: Exit Multiples | B9: 7.5
A11: Exit Enterprise Value | B11: =B8*B9 -> 8203.5
A13: Net debt at the Exit | B13: 277.3
A15: Equity Value at Exit | B15: =B11-B13 -> 7926.2
A18: Equity Returns | B18: Column1 | C18: Year 1 | D18: Year 2 | E18: Year 3 | F18: Year 4 | G18: Year 5
A19: Equity Invested Year LTM | B19: -4520 | C19: 0 | D19: 0 | E19: 0 | F19: 0 | G19: 7926.2
A20: Exit Proceeds Year 5 | B20: 7926.3
A22: MOIC | B22: 1.75
A23: IRR | B23: =IRR(B19:G19) -> 0.11888466
A26: IRR vs EXIT multiple
A27: Exit Multiples | B27: 6.5 | C27: 7 | D27: 7.5 | E27: 8 | F27: 8.5
A28: IRR | B28: 0.089 | C28: 0.104 | D28: 0.12 | E28: 0.135 | F28: 0.15
A31: IRR vs Capital Structure
A32: Debt/ Equity | B32: 60/40 | C32: 65/35 | D32: 70/30
A33: Equity Invested | B33: 3312 | C33: 4520 | D33: 5728
A34: IRR | B34: 0.102 | C34: 0.12 | D34: 0.138
A35: MOIC | B35: 1.55 | C35: 1.75 | D35: 1.95

Sheet Trading Comps Summary
A3: Peer Group
A4: ADT Inc
A5: Arlo Technology
A6: Alarm.com
A7: Resideo Technology
A10: Trading Multiples Statistics
A11: EV/ EBITDA | B11: Multiples
A12: 25th Percentile | B12: 6.8
A13: Median | B13: 7.5
A14: 75th Percentile | B14: 8.1
A16: Implied Valuation
A17: Item | B17: Value
A18: Exit EBITDA | B18: 1093.8
A20: Enterprise Value Range
A21: Muliple Case | B21: EV/ EBITDA | C21: Enterprise Value
A22: Low | B22: =B12 -> 6.8 | C22: =B22*B18 -> 7437.84
A23: Median | B23: =B13 -> 7.5 | C23: =B23*B18 -> 8203.5
A24: High | B24: =B14 -> 8.1 | C24: =B24*B18 -> 8859.78
A26: Equity Value Bridge
A27: Item | B27: Low | C27: Median | D27: High
A28: Enterprise Value | B28: =C22 -> 7437.84 | C28: =C23 -> 8203.5 | D28: =C24 -> 8859.78
A29: Net Debt | B29: =277.3 -> 277.3 | C29: =277.3 -> 277.3 | D29: =277.3 -> 277.3
A30: Equity Value | B30: =B28-B29 -> 7160.54 | C30: =C28-C29 -> 7926.2 | D30: =D28-D29 -> 8582.48

Sheet DCF Summary
A2: Valauation Method | B2: Unleveraged DCF
A3: Currency | B3: USD mm
A4: Base Year | B4: 2025
A5: Projection Period | B5: 2026-2030
A6: Terminal Year | B6: 2030
A8: WAAC | B8: 0.08
A9: Terminal Growth Rate | B9: 0.02
A10: Projection Period | B10: 5
A11: Terminal Value Method | B11: Prepetuity Growth
A14: Unlevered free Cash Flow
A15: Year | B15: UFCF
A16: Year 1 | B16: ='Operating Model'!C22 -> 632.17657
A17: Year 2 | B17: ='Operating Model'!D22 -> 651.14397
A18: Year 3 | B18: ='Operating Model'!E22 -> 677.42434
A19: Year 4 | B19: ='Operating Model'!F22 -> 703.78513
A20: Year 5 | B20: ='Operating Model'!G22 -> 731.10865
A22: DCF Component | B22: Values
A23: PV of UFCF | B23: 2635
A24: Terminal Value | B24: 7980
A25: PV of Terminal Value | B25: =B24-B23 -> 5345
A26: Enterprise Value | B26: 8175
A28: Equity Value Bridge | B28: Values
A29: Enterprise Value (DCF) | B29: =B26 -> 8175
A30: Net Debt | B30: 277.3
A31: Equity Value Bridge | B31: =B29-B30 -> 7897.7
A33: Implied Value Range | B33: 1.50% | C33: 2.00% | D33: 2.50%
A34: WAAC/ TG
A35: 0.075 | B35: 8520 | C35: 8980 | D35: 9470
A36: 0.08 | B36: 7650 | C36: 8175 | D36: 8740
A37: 0.085 | B37: 6920 | C37: 9420 | D37: 7960

Sheet Appendix
A1: Appendix A | B1: Trading Comps Details
A3: Metrics | B3: ADT inc | C3: Arlo Technologies | D3: Alarm.com | E3: Resideo Technologies
A4: Year of Acquring | B4: 2018 | C4: 2010 | D4: 2015 | E4: 2018
A6: Share Price | B6: 8.07 | C6: 10.96 | D6: 51.02 | E6: 35.16
A7: Diluted shares Outstanding | B7: 819.7 | C7: 87.3 | D7: 49.76 | E7: 147.9
A8: Equity Value | B8: =B6*B7 -> 6614.979 | C8: =C6*C7 -> 956.808 | D8: =D6*D7 -> 2538.7552 | E8: =E6*E7 -> 5200.164
A11: Short Term Debt | B11: 521.7 | C11: - | D11: 499 | E11: 0
A12: Long Term Debt | B12: 7284.1 | C12: - | D12: 488.922 | E12: 1432
A13: Capital Leases | B13: 0 | C13: - | D13: 0 | E13: 0
A14: Total Debt | B14: =B11+B12 -> 7805.8 | D14: =D11+D12+D13 -> 987.922 | E14: 1432
A15: Cash and Cash Equivalents | B15: 62.8 | C15: 8601.2 | D15: 1066.583 | E15: 416.7
A16: Restricted Cash | B16: 108.2 | C16: - | D16: 8.316 | E16: 24.3
A17: Net Debt | B17: =B14-B15 -> 7743 | C17: =C14-C15 -> -8601.2 | D17: =D14-D15 -> -78.661 | E17: =E14-E15 -> 1015.3
A19: Enterprise Value | B19: =B8+B17 -> 14357.979 | C19: =C8+C17 -> -7644.392 | D19: =D8+D17 -> 2460.0942 | E19: =E8+E17 -> 6215.464
A22: Minority Interest | B22: 0 | C22: 0 | D22: 0 | E22: 0
A23: Preferref Equity | B23: 0 | C23: 0 | D23: 0 | E23: 0
A24: Penison/ Other | B24: 0 | C24: 0 | D24: 0 | E24: 0
A25: Adjested Enterpeise Value | B25: =SUM(B19:B24) -> 14357.979 | C25: =SUM(C19:C24) -> -7644.392 | D25: =SUM(D19:D24) -> 2460.0942 | E25: =SUM(E19:E24) -> 6215.464
A29: Appendix B | B29: Trading Comps Implied Valuation
A31: Metrics | B31: Minimun | C31: Median | D31: Maximum | G31: Multiples
A32: EV/Revenue | B32: 0.9 | C32: 2.3 | D32: 2.9 | G32: Metrics | H32: ADT inc | I32: Arlo Technologies | J32: Alarm.com | K32: Resideo Technologies
A33: EV/ EBITDA | B33: 6.8 | C33: 6.9 | D33: 10.4 | G33: Share Price | H33: 8.07 | I33: 10.96 | J33: 51.02 | K33: 35.16
G34: Diluted shares Outstanding | H34: 819.7 | I34: 109.6 | J34: 49.76 | K34: 147.9
A35: ADT | B35: Values | G35: Equity Value | H35: =H33*H34 -> 6614.979 | I35: =I33*I34 -> 1201.216 | J35: =J33*J34 -> 2538.7552 | K35: =K33*K34 -> 5200.164
A36: LTM revenue | B36: 4923 | G36: Net Debt | H36: =Appendix!B17 -> 7743 | I36: -165.5 | J36: =Appendix!D17 -> -78.661 | K36: =Appendix!E17 -> 1015.3
A37: LTM EBITDA | B37: 2121 | G37: Enterprise Value | H37: =Appendix!B19 -> 14357.979 | I37: =I35-(-I36) -> 1035.716 | J37: =Appendix!D19 -> 2460.0942 | K37: =Appendix!E19 -> 6215.464
A39: Implied Enterpise Value | G39: LTM Revenue | H39: 4923 | I39: 512 | J39: 936 | K39: 6945
A40: Min | B40: =B32*B36 -> 4430.7 | G40: EBITDA | H40: 2121 | I40: -54 | J40: 237 | K40: 905
A41: Median | B41: =C32*B36 -> 11322.9 | G41: EBITDA Margin | H41: =H40/H39 -> 0.43083486 | I41: NM | J41: =J40/J39 -> 0.25320513 | K41: =K40/K39 -> 0.13030958
A42: Max | B42: =D32*B36 -> 14276.7
A44: Implied EBITDA | G44: Metrics | H44: Values | I44: Values2 | J44: Values3 | K44: Values4
A45: Min | B45: =B33*B37 -> 14422.8 | G45: Equity Value/ EBITDA | H45: =H37/H40 -> 6.7694385 | I45: NM | J45: =J37/J40 -> 10.380144 | K45: =K37/K40 -> 6.867916
A46: Median | B46: =C33*B37 -> 14634.9
A47: Max | B47: =D33*B37 -> 22058.4 | G47: Equity Value / Revenue | H47: =H37/H39 -> 2.9165101 | I47: =I37/I39 -> 2.0228828 | J47: =J37/J39 -> 2.6283058 | K47: =K37/K39 -> 0.89495522
A49: Bridge to Equity | B49: Column1 | C49: Column2 | D49: Column3
A50: EV/ Revenue | B50: =B40-Appendix!B17 -> -3312.3 | C50: =B41-Appendix!B17 -> 3579.9 | D50: =B42-Appendix!B17 -> 6533.7
A51: EV/ EBITDA | B51: =B45-Appendix!B17 -> 6679.8 | C51: =B46-7743 -> 6891.9 | D51: =B47-7743 -> 14315.4 | G51: Summary Statistics | H51: EV/ Revenue | I51: EV/ EBITDA
A52: Implied Share Price | G52: Mimimum | H52: =MIN(H47:K47) -> 0.89495522 | I52: =MIN(H45:K45) -> 6.7694385
A53: ADT shares outstanding | B53: 819.7 | G53: Median | H53: =MEDIAN(H47:K47) -> 2.3255943 | I53: =MEDIAN(H45:K45) -> 6.867916
A54: EV/ Revenue | B54: =B50/B53 -> -4.0408686 | C54: =C50/B53 -> 4.3673295 | D54: =D50/B53 -> 7.970843 | G54: Maximum | H54: =MAX(H47:K47) -> 2.9165101 | I54: =MAX(J45:K45) -> 10.380144
...
